<?xml version="1.0" ?>
<robot name="new_robot" xmlns:xacro="http://ros.org/wiki/xacro">
  <material name="black">
      <color rgba="0.0 0.0 0.0 1.0"/>
  </material>

  <material name="dark">
    <color rgba="0.3 0.3 0.3 1.0"/>
  </material>
  
  <material name="grey">
    <color rgba="0.5 0.5 0.5 1.0"/>
  </material>

  <material name="orange">
    <color rgba="1 0.4235 0.0392 1.0"/>
  </material>
   <material name="blue">
    <color rgba="0.0 0.0 0.8 1.0"/>
  </material>
  
  <material name="light_black">
    <color rgba="0.8 0.8 0.8 1.0"/>
  </material>
  <!--<xacro:include filename="$(find ppp_robot)/urdf/colors.xacro"/>-->
  <xacro:include filename="$(find ppp_robot)/urdf/ppp_robot.gazebo.xacro"/>

  <link name="world"/>
  
  <joint name="base_joint" type="fixed">
    <parent link="world"/>
    <child link="base_link"/>
    <origin xyz="0 0 0.085" rpy="0 0 0"/>
  </joint>
  
  <link name="base_link">
    <visual>
      <origin xyz="0 0 0.0" rpy="0 0 0"/>
      <geometry>
        <mesh filename="package://ppp_robot/mesh/base.stl" scale="1 1 1"/>
        <!--<box size="4.0 4.0 0.2"/>-->
      </geometry>
      <material name="light_black"/>
       
        
    </visual>

    <collision>
      <origin xyz="0 0 0.030" rpy="0 0 0"/>
      <geometry>
        <box size="4.0 4.0 0.2"/>
        
      </geometry>
    </collision>

    <inertial>
      <origin xyz="0 0 0" rpy="0 0 0"/>
      <mass value="1.3729096e+00"/>
      <inertia ixx="8.7002718e-03" ixy="-4.7576583e-05" ixz="1.1160499e-04"
               iyy="8.6195418e-03" iyz="-3.5422299e-06"
               izz="1.4612727e-02" />
    </inertial>
  </link>
  
  <joint name="first_axis_joint" type="prismatic">
    <parent link="base_link"/>
    <child link="first_axis_link"/>
    <origin xyz="0 -1.65 2.98" rpy="0 0 0"/>
    <axis xyz="0 1 0"/>
    <limit lower="0" upper="3.3" velocity="100" effort="100"/>
  </joint>
  
  <link name="first_axis_link">
    <visual>
      <origin xyz="0 0 0" rpy="0 0 0"/>
      <geometry>
        <mesh filename="package://ppp_robot/mesh/first_axis.stl" scale="1 1 1"/>
      </geometry>
      <material name="dark"/>
       
        
    </visual>

    <collision>
      <origin xyz="0 0 0" rpy="0 0 0"/>
      <geometry>
        <box size="4.2 0.24 0.26"/>
        
      </geometry>
    </collision>

    <inertial>
      <origin xyz="0 0 0" rpy="0 0 0"/>
      <mass value="1.3729096e+00"/>
      <inertia ixx="8.7002718e-03" ixy="-4.7576583e-05" ixz="1.1160499e-04"
               iyy="8.6195418e-03" iyz="-3.5422299e-06"
               izz="1.4612727e-02" />
    </inertial>
  </link>
  
  <joint name="second_axis_joint" type="prismatic">
    <parent link="first_axis_link"/>
    <child link="second_axis_link"/>
    <origin xyz="-1.65 0.08 0" rpy="0 0 0"/>
    <axis xyz="1 0 0"/>
    <limit lower="0" upper="3.3" velocity="100" effort="100"/>
  </joint>
  
  <link name="second_axis_link">
    <visual>
      <origin xyz="0 0 0" rpy="0 0 0"/>
      <geometry>
        <mesh filename="package://ppp_robot/mesh/second_axis.stl" scale="1 1 1"/>
      </geometry>
      <material name="orange"/>
       
        
    </visual>

    <collision>
      <origin xyz="0 0 0" rpy="0 0 0"/>
      <geometry>
        <box size="0.26 0.5 0.4"/>
        
      </geometry>
    </collision>

    <inertial>
      <origin xyz="0 0 0" rpy="0 0 0"/>
      <mass value="1.3729096e+00"/>
      <inertia ixx="8.7002718e-03" ixy="-4.7576583e-05" ixz="1.1160499e-04"
               iyy="8.6195418e-03" iyz="-3.5422299e-06"
               izz="1.4612727e-02" />
    </inertial>
  </link>

	
  
  
  <joint name="third_axis_joint" type="prismatic">
    <parent link="second_axis_link"/>
    <child link="third_axis_link"/>
    <origin xyz="0 0.12 0.02" rpy="0 0 0"/>
    <axis xyz="0 0 -1"/>
    <limit lower="0" upper="1" velocity="100" effort="100"/>
  </joint>
  
  <link name="third_axis_link">
    <visual>
      <origin xyz="0 0 0" rpy="0 0 0"/>
      <geometry>
        <mesh filename="package://ppp_robot/mesh/third_axis.stl" scale="1 1 1"/>
      </geometry>
      <material name="black"/>
       
        
    </visual>

    <collision>
      <origin xyz="0 0 0" rpy="0 0 0"/>
      <geometry>
        <cylinder length="2.58" radius="0.12"/>
        
      </geometry>
    </collision>

    <inertial>
      <origin xyz="0 0 0" rpy="0 0 0"/>
      <mass value="1.3729096e+00"/>
      <inertia ixx="8.7002718e-03" ixy="-4.7576583e-05" ixz="1.1160499e-04"
               iyy="8.6195418e-03" iyz="-3.5422299e-06"
               izz="1.4612727e-02" />
    </inertial>
  </link>

  
  
  

  



</robot>
